Workbook

Sheet libro compras
H1: S/. | I1: $ | K1: =+#REF!*#REF! -> #REF! | N1: TIPO DOC SUNAT | T1: TIPO DOC ISCALA | AB1: 0136 | AI1: 281110 | AJ1: 401110 | AK1: 431202
A2: SEQ | B2: ASSIENTO | C2: CODPRVEEDOR | D2: NUMERO DE FACTURA | E2: FECHA FACT | F2: FECHA CONT | G2: FECHA VENC | H2: Importe Facturado | I2: Importe Facturado Org | J2: COD MONEDA | K2: Tipo de cambio | L2: IVA | M2: Código Banco Central | N2: Cód. de Autorización | O2: Comentarios | P2: CADENA DE CONT | Q2: CADENA DE CONT | R2: CADENA DE CONT | S2: CADENA DE CONT | T2: TIPO DE FACTURA | U2: CODIGO CARGA FISCAL | V2: Tipo IVA Código impuest | W2: Base imponible Registro impues | X2: Importe IVA Código impuest | Y2: Tipo IVA Registro impuest | Z2: Fecha Transacción Registro Impues | AB2: V.V | AC2: IGV | AD2: P.V | AE2: TC | AF2: V.V | AG2: IGV | AH2: P.V | AI2: V.V | AJ2: IGV | AK2: P.V | AL2: DIFERENCIA | AM2: FECHA FACTURA | AQ2: FECHA FACTURA | AR2: FECHA PAGO | AV2: FECHA PAGO
A3: 1 | E3: =+AQ3 | G3: =+AV3 -> 000100 | H3: =+AK3 -> 0 | I3: =+ROUND(AD3,2) -> 0 | K3: =+AE3 -> 0 | L3: =+AJ3 -> 0 | M3: 101 | P3: =+VLOOKUP(C3,Hoja1!$A$4:$C$57,3,FALSE) -> #N/A | Q3: 103 | S3: =(RIGHT(O3,7)) | U3: RC100 | V3: C001 | W3: =+AI3 -> 0 | X3: =+AJ3 -> 0 | Y3: 1 | Z3: =+F3 -> 0 | AC3: 0 | AD3: =+AB3+AC3 -> 0 | AF3: =+AB3*AE3 -> 0 | AG3: =+AC3*AE3 -> 0 | AH3: =+AD3*AE3 -> 0 | AI3: =+ROUND(AF3,2) -> 0 | AJ3: =+ROUND(AG3,2) -> 0 | AK3: =+ROUND(AH3,2) -> 0 | AL3: =+AI3+AJ3-AK3 -> 0 | AN3: =+LEFT(AM3,2) | AO3: =+MID(AM3,4,2) | AP3: =+RIGHT(AM3,2) | AQ3: =+CONCATENATE(AN3,AO3,AP3) | AR3: =AM3+_xlfn.XLOOKUP(C3,Hoja1!A:A,Hoja1!B:B) -> 0 | AS3: =+DAY(AR3) -> 0 | AT3: =+MONTH(AR3) -> 1 | AU3: =+YEAR(AR3) -> 1900 | AV3: =+CONCATENATE(TEXT(AS3,"00"),TEXT(AT3,"00"),RIGHT(AU3,2)) -> 000100
A7: =1+A3 -> 2 | E7: =+AQ7 | G7: =+AV7 -> 000100 | H7: =+AK7 -> 0 | I7: =+ROUND(AD7,2) -> 0 | K7: =+AE7 -> 0 | L7: =+AJ7 -> 0 | M7: 101 | P7: =+VLOOKUP(C7,Hoja1!$A$4:$C$57,3,FALSE) -> #N/A | Q7: 103 | S7: =(RIGHT(O7,7)) | U7: RC100 | V7: C001 | W7: =+AI7 -> 0 | X7: =+AJ7 -> 0 | Y7: 1 | Z7: =+F7 -> 0 | AC7: 0 | AD7: =+AB7+AC7 -> 0 | AF7: =+AB7*AE7 -> 0 | AG7: =+AC7*AE7 -> 0 | AH7: =+AD7*AE7 -> 0 | AI7: =+ROUND(AF7,2) -> 0 | AJ7: =+ROUND(AG7,2) -> 0 | AK7: =+ROUND(AH7,2) -> 0 | AL7: =+AI7+AJ7-AK7 -> 0 | AN7: =+LEFT(AM7,2) | AO7: =+MID(AM7,4,2) | AP7: =+RIGHT(AM7,2) | AQ7: =+CONCATENATE(AN7,AO7,AP7) | AR7: =AM7+_xlfn.XLOOKUP(C7,Hoja1!A:A,Hoja1!B:B) -> 0 | AS7: =+DAY(AR7) -> 0 | AT7: =+MONTH(AR7) -> 1 | AU7: =+YEAR(AR7) -> 1900 | AV7: =+CONCATENATE(TEXT(AS7,"00"),TEXT(AT7,"00"),RIGHT(AU7,2)) -> 000100
A11: =1+A7 -> 3 | E11: =+AQ11 | G11: =+AV11 -> 000100 | H11: =+AK11 -> 0 | I11: =+ROUND(AD11,2) -> 0 | K11: =+AE11 -> 0 | L11: =+AJ11 -> 0 | M11: 101 | P11: =+VLOOKUP(C11,Hoja1!$A$4:$C$57,3,FALSE) -> #N/A | Q11: 103 | S11: =(RIGHT(O11,7)) | U11: RC100 | V11: C001 | W11: =+AI11 -> 0 | X11: =+AJ11 -> 0 | Y11: 1 | Z11: =+F11 -> 0 | AC11: 0 | AD11: =+AB11+AC11 -> 0 | AF11: =+AB11*AE11 -> 0 | AG11: =+AC11*AE11 -> 0 | AH11: =+AD11*AE11 -> 0 | AI11: =+ROUND(AF11,2) -> 0 | AJ11: =+ROUND(AG11,2) -> 0 | AK11: =+ROUND(AH11,2) -> 0 | AL11: =+AI11+AJ11-AK11 -> 0 | AN11: =+LEFT(AM11,2) | AO11: =+MID(AM11,4,2) | AP11: =+RIGHT(AM11,2) | AQ11: =+CONCATENATE(AN11,AO11,AP11) | AR11: =AM11+_xlfn.XLOOKUP(C11,Hoja1!A:A,Hoja1!B:B) -> 0 | AS11: =+DAY(AR11) -> 0 | AT11: =+MONTH(AR11) -> 1 | AU11: =+YEAR(AR11) -> 1900 | AV11: =+CONCATENATE(TEXT(AS11,"00"),TEXT(AT11,"00"),RIGHT(AU11,2)) -> 000100
A15: =1+A11 -> 4 | E15: =+AQ15 | G15: =+AV15 -> 000100 | H15: =+AK15 -> 0 | I15: =+ROUND(AD15,2) -> 0 | K15: =+AE15 -> 0 | L15: =+AJ15 -> 0 | M15: 101 | P15: =+VLOOKUP(C15,Hoja1!$A$4:$C$57,3,FALSE) -> #N/A | Q15: 103 | S15: =(RIGHT(O15,7)) | U15: RC100 | V15: C001 | W15: =+AI15 -> 0 | X15: =+AJ15 -> 0 | Y15: 1 | Z15: =+F15 -> 0 | AC15: 0 | AD15: =+AB15+AC15 -> 0 | AF15: =+AB15*AE15 -> 0 | AG15: =+AC15*AE15 -> 0 | AH15: =+AD15*AE15 -> 0 | AI15: =+ROUND(AF15,2) -> 0 | AJ15: =+ROUND(AG15,2) -> 0 | AK15: =+ROUND(AH15,2) -> 0 | AL15: =+AI15+AJ15-AK15 -> 0 | AN15: =+LEFT(AM15,2) | AO15: =+MID(AM15,4,2) | AP15: =+RIGHT(AM15,2) | AQ15: =+CONCATENATE(AN15,AO15,AP15) | AR15: =AM15+_xlfn.XLOOKUP(C15,Hoja1!A:A,Hoja1!B:B) -> 0 | AS15: =+DAY(AR15) -> 0 | AT15: =+MONTH(AR15) -> 1 | AU15: =+YEAR(AR15) -> 1900 | AV15: =+CONCATENATE(TEXT(AS15,"00"),TEXT(AT15,"00"),RIGHT(AU15,2)) -> 000100
A19: =1+A15 -> 5 | E19: =+AQ19 | G19: =+AV19 -> 000100 | H19: =+AK19 -> 0 | I19: =+ROUND(AD19,2) -> 0 | K19: =+AE19 -> 0 | L19: =+AJ19 -> 0 | M19: 101 | P19: =+VLOOKUP(C19,Hoja1!$A$4:$C$57,3,FALSE) -> #N/A | Q19: 103 | S19: =(RIGHT(O19,7)) | U19: RC100 | V19: C001 | W19: =+AI19 -> 0 | X19: =+AJ19 -> 0 | Y19: 1 | Z19: =+F19 -> 0 | AC19: 0 | AD19: =+AB19+AC19 -> 0 | AF19: =+AB19*AE19 -> 0 | AG19: =+AC19*AE19 -> 0 | AH19: =+AD19*AE19 -> 0 | AI19: =+ROUND(AF19,2) -> 0 | AJ19: =+ROUND(AG19,2) -> 0 | AK19: =+ROUND(AH19,2) -> 0 | AL19: =+AI19+AJ19-AK19 -> 0 | AN19: =+LEFT(AM19,2) | AO19: =+MID(AM19,4,2) | AP19: =+RIGHT(AM19,2) | AQ19: =+CONCATENATE(AN19,AO19,AP19) | AR19: =AM19+_xlfn.XLOOKUP(C19,Hoja1!A:A,Hoja1!B:B) -> 0 | AS19: =+DAY(AR19) -> 0 | AT19: =+MONTH(AR19) -> 1 | AU19: =+YEAR(AR19) -> 1900 | AV19: =+CONCATENATE(TEXT(AS19,"00"),TEXT(AT19,"00"),RIGHT(AU19,2)) -> 000100
A23: =1+A19 -> 6 | E23: =+AQ23 | G23: =+AV23 -> 000100 | H23: =+AK23 -> 0 | I23: =+ROUND(AD23,2) -> 0 | K23: =+AE23 -> 0 | L23: =+AJ23 -> 0 | M23: 101 | P23: =+VLOOKUP(C23,Hoja1!$A$4:$C$57,3,FALSE) -> #N/A | Q23: 103 | S23: =(RIGHT(O23,7)) | U23: RC100 | V23: C001 | W23: =+AI23 -> 0 | X23: =+AJ23 -> 0 | Y23: 1 | Z23: =+F23 -> 0 | AC23: 0 | AD23: =+AB23+AC23 -> 0 | AF23: =+AB23*AE23 -> 0 | AG23: =+AC23*AE23 -> 0 | AH23: =+AD23*AE23 -> 0 | AI23: =+ROUND(AF23,2) -> 0 | AJ23: =+ROUND(AG23,2) -> 0 | AK23: =+ROUND(AH23,2) -> 0 | AL23: =+AI23+AJ23-AK23 -> 0 | AN23: =+LEFT(AM23,2) | AO23: =+MID(AM23,4,2) | AP23: =+RIGHT(AM23,2) | AQ23: =+CONCATENATE(AN23,AO23,AP23) | AR23: =AM23+_xlfn.XLOOKUP(C23,Hoja1!A:A,Hoja1!B:B) -> 0 | AS23: =+DAY(AR23) -> 0 | AT23: =+MONTH(AR23) -> 1 | AU23: =+YEAR(AR23) -> 1900 | AV23: =+CONCATENATE(TEXT(AS23,"00"),TEXT(AT23,"00"),RIGHT(AU23,2)) -> 000100
A27: =1+A23 -> 7 | E27: =+AQ27 | G27: =+AV27 -> 000100 | H27: =+AK27 -> 0 | I27: =+ROUND(AD27,2) -> 0 | K27: =+AE27 -> 0 | L27: =+AJ27 -> 0 | M27: 101 | P27: =+VLOOKUP(C27,Hoja1!$A$4:$C$57,3,FALSE) -> #N/A | Q27: 103 | S27: =(RIGHT(O27,7)) | U27: RC100 | V27: C001 | W27: =+AI27 -> 0 | X27: =+AJ27 -> 0 | Y27: 1 | Z27: =+F27 -> 0 | AC27: 0 | AD27: =+AB27+AC27 -> 0 | AF27: =+AB27*AE27 -> 0 | AG27: =+AC27*AE27 -> 0 | AH27: =+AD27*AE27 -> 0 | AI27: =+ROUND(AF27,2) -> 0 | AJ27: =+ROUND(AG27,2) -> 0 | AK27: =+ROUND(AH27,2) -> 0 | AL27: =+AI27+AJ27-AK27 -> 0 | AN27: =+LEFT(AM27,2) | AO27: =+MID(AM27,4,2) | AP27: =+RIGHT(AM27,2) | AQ27: =+CONCATENATE(AN27,AO27,AP27) | AR27: =AM27+_xlfn.XLOOKUP(C27,Hoja1!A:A,Hoja1!B:B) -> 0 | AS27: =+DAY(AR27) -> 0 | AT27: =+MONTH(AR27) -> 1 | AU27: =+YEAR(AR27) -> 1900 | AV27: =+CONCATENATE(TEXT(AS27,"00"),TEXT(AT27,"00"),RIGHT(AU27,2)) -> 000100
A31: =1+A27 -> 8 | E31: =+AQ31 | G31: =+AV31 -> 000100 | H31: =+AK31 -> 0 | I31: =+ROUND(AD31,2) -> 0 | K31: =+AE31 -> 0 | L31: =+AJ31 -> 0 | M31: 101 | P31: =+VLOOKUP(C31,Hoja1!$A$4:$C$57,3,FALSE) -> #N/A | Q31: 103 | S31: =(RIGHT(O31,7)) | U31: RC100 | V31: C001 | W31: =+AI31 -> 0 | X31: =+AJ31 -> 0 | Y31: 1 | Z31: =+F31 -> 0 | AC31: 0 | AD31: =+AB31+AC31 -> 0 | AF31: =+AB31*AE31 -> 0 | AG31: =+AC31*AE31 -> 0 | AH31: =+AD31*AE31 -> 0 | AI31: =+ROUND(AF31,2) -> 0 | AJ31: =+ROUND(AG31,2) -> 0 | AK31: =+ROUND(AH31,2) -> 0 | AL31: =+AI31+AJ31-AK31 -> 0 | AN31: =+LEFT(AM31,2) | AO31: =+MID(AM31,4,2) | AP31: =+RIGHT(AM31,2) | AQ31: =+CONCATENATE(AN31,AO31,AP31) | AR31: =AM31+_xlfn.XLOOKUP(C31,Hoja1!A:A,Hoja1!B:B) -> 0 | AS31: =+DAY(AR31) -> 0 | AT31: =+MONTH(AR31) -> 1 | AU31: =+YEAR(AR31) -> 1900 | AV31: =+CONCATENATE(TEXT(AS31,"00"),TEXT(AT31,"00"),RIGHT(AU31,2)) -> 000100
A35: =1+A31 -> 9 | E35: =+AQ35 | G35: =+AV35 -> 000100 | H35: =+AK35 -> 0 | I35: =+ROUND(AD35,2) -> 0 | K35: =+AE35 -> 0 | L35: =+AJ35 -> 0 | M35: 101 | P35: =+VLOOKUP(C35,Hoja1!$A$4:$C$57,3,FALSE) -> #N/A | Q35: 103 | S35: =(RIGHT(O35,7)) | U35: RC100 | V35: C001 | W35: =+AI35 -> 0 | X35: =+AJ35 -> 0 | Y35: 1 | Z35: =+F35 -> 0 | AC35: 0 | AD35: =+AB35+AC35 -> 0 | AF35: =+AB35*AE35 -> 0 | AG35: =+AC35*AE35 -> 0 | AH35: =+AD35*AE35 -> 0 | AI35: =+ROUND(AF35,2) -> 0 | AJ35: =+ROUND(AG35,2) -> 0 | AK35: =+ROUND(AH35,2) -> 0 | AL35: =+AI35+AJ35-AK35 -> 0 | AN35: =+LEFT(AM35,2) | AO35: =+MID(AM35,4,2) | AP35: =+RIGHT(AM35,2) | AQ35: =+CONCATENATE(AN35,AO35,AP35) | AR35: =AM35+_xlfn.XLOOKUP(C35,Hoja1!A:A,Hoja1!B:B) -> 0 | AS35: =+DAY(AR35) -> 0 | AT35: =+MONTH(AR35) -> 1 | AU35: =+YEAR(AR35) -> 1900 | AV35: =+CONCATENATE(TEXT(AS35,"00"),TEXT(AT35,"00"),RIGHT(AU35,2)) -> 000100
A39: =1+A35 -> 10 | E39: =+AQ39 | G39: =+AV39 -> 000100 | H39: =+AK39 -> 0 | I39: =+ROUND(AD39,2) -> 0 | K39: =+AE39 -> 0 | L39: =+AJ39 -> 0 | M39: 101 | P39: =+VLOOKUP(C39,Hoja1!$A$4:$C$57,3,FALSE) -> #N/A | Q39: 103 | S39: =(RIGHT(O39,7)) | U39: RC100 | V39: C001 | W39: =+AI39 -> 0 | X39: =+AJ39 -> 0 | Y39: 1 | Z39: =+F39 -> 0 | AC39: 0 | AD39: =+AB39+AC39 -> 0 | AF39: =+AB39*AE39 -> 0 | AG39: =+AC39*AE39 -> 0 | AH39: =+AD39*AE39 -> 0 | AI39: =+ROUND(AF39,2) -> 0 | AJ39: =+ROUND(AG39,2) -> 0 | AK39: =+ROUND(AH39,2) -> 0 | AL39: =+AI39+AJ39-AK39 -> 0 | AN39: =+LEFT(AM39,2) | AO39: =+MID(AM39,4,2) | AP39: =+RIGHT(AM39,2) | AQ39: =+CONCATENATE(AN39,AO39,AP39) | AR39: =AM39+_xlfn.XLOOKUP(C39,Hoja1!A:A,Hoja1!B:B) -> 0 | AS39: =+DAY(AR39) -> 0 | AT39: =+MONTH(AR39) -> 1 | AU39: =+YEAR(AR39) -> 1900 | AV39: =+CONCATENATE(TEXT(AS39,"00"),TEXT(AT39,"00"),RIGHT(AU39,2)) -> 000100
A43: =1+A39 -> 11 | E43: =+AQ43 | G43: =+AV43 -> 000100 | H43: =+AK43 -> 0 | I43: =+ROUND(AD43,2) -> 0 | K43: =+AE43 -> 0 | L43: =+AJ43 -> 0 | M43: 101 | P43: =+VLOOKUP(C43,Hoja1!$A$4:$C$57,3,FALSE) -> #N/A | Q43: 103 | S43: =(RIGHT(O43,7)) | U43: RC100 | V43: C001 | W43: =+AI43 -> 0 | X43: =+AJ43 -> 0 | Y43: 1 | Z43: =+F43 -> 0 | AC43: 0 | AD43: =+AB43+AC43 -> 0 | AF43: =+AB43*AE43 -> 0 | AG43: =+AC43*AE43 -> 0 | AH43: =+AD43*AE43 -> 0 | AI43: =+ROUND(AF43,2) -> 0 | AJ43: =+ROUND(AG43,2) -> 0 | AK43: =+ROUND(AH43,2) -> 0 | AL43: =+AI43+AJ43-AK43 -> 0 | AN43: =+LEFT(AM43,2) | AO43: =+MID(AM43,4,2) | AP43: =+RIGHT(AM43,2) | AQ43: =+CONCATENATE(AN43,AO43,AP43) | AR43: =AM43+_xlfn.XLOOKUP(C43,Hoja1!A:A,Hoja1!B:B) -> 0 | AS43: =+DAY(AR43) -> 0 | AT43: =+MONTH(AR43) -> 1 | AU43: =+YEAR(AR43) -> 1900 | AV43: =+CONCATENATE(TEXT(AS43,"00"),TEXT(AT43,"00"),RIGHT(AU43,2)) -> 000100
A47: =1+A43 -> 12 | E47: =+AQ47 | G47: =+AV47 -> 000100 | H47: =+AK47 -> 0 | I47: =+ROUND(AD47,2) -> 0 | K47: =+AE47 -> 0 | L47: =+AJ47 -> 0 | M47: 101 | P47: =+VLOOKUP(C47,Hoja1!$A$4:$C$57,3,FALSE) -> #N/A | Q47: 103 | S47: =(RIGHT(O47,7)) | U47: RC100 | V47: C001 | W47: =+AI47 -> 0 | X47: =+AJ47 -> 0 | Y47: 1 | Z47: =+F47 -> 0 | AC47: 0 | AD47: =+AB47+AC47 -> 0 | AF47: =+AB47*AE47 -> 0 | AG47: =+AC47*AE47 -> 0 | AH47: =+AD47*AE47 -> 0 | AI47: =+ROUND(AF47,2) -> 0 | AJ47: =+ROUND(AG47,2) -> 0 | AK47: =+ROUND(AH47,2) -> 0 | AL47: =+AI47+AJ47-AK47 -> 0 | AN47: =+LEFT(AM47,2) | AO47: =+MID(AM47,4,2) | AP47: =+RIGHT(AM47,2) | AQ47: =+CONCATENATE(AN47,AO47,AP47) | AR47: =AM47+_xlfn.XLOOKUP(C47,Hoja1!A:A,Hoja1!B:B) -> 0 | AS47: =+DAY(AR47) -> 0 | AT47: =+MONTH(AR47) -> 1 | AU47: =+YEAR(AR47) -> 1900 | AV47: =+CONCATENATE(TEXT(AS47,"00"),TEXT(AT47,"00"),RIGHT(AU47,2)) -> 000100
A51: =1+A47 -> 13 | E51: =+AQ51 | G51: =+AV51 -> 000100 | H51: =+AK51 -> 0 | I51: =+ROUND(AD51,2) -> 0 | K51: =+AE51 -> 0 | L51: =+AJ51 -> 0 | M51: 101 | P51: =+VLOOKUP(C51,Hoja1!$A$4:$C$57,3,FALSE) -> #N/A | Q51: 103 | S51: =(RIGHT(O51,7)) | U51: RC100 | V51: C001 | W51: =+AI51 -> 0 | X51: =+AJ51 -> 0 | Y51: 1 | Z51: =+F51 -> 0 | AC51: 0 | AD51: =+AB51+AC51 -> 0 | AF51: =+AB51*AE51 -> 0 | AG51: =+AC51*AE51 -> 0 | AH51: =+AD51*AE51 -> 0 | AI51: =+ROUND(AF51,2) -> 0 | AJ51: =+ROUND(AG51,2) -> 0 | AK51: =+ROUND(AH51,2) -> 0 | AL51: =+AI51+AJ51-AK51 -> 0 | AN51: =+LEFT(AM51,2) | AO51: =+MID(AM51,4,2) | AP51: =+RIGHT(AM51,2) | AQ51: =+CONCATENATE(AN51,AO51,AP51) | AR51: =AM51+_xlfn.XLOOKUP(C51,Hoja1!A:A,Hoja1!B:B) -> 0 | AS51: =+DAY(AR51) -> 0 | AT51: =+MONTH(AR51) -> 1 | AU51: =+YEAR(AR51) -> 1900 | AV51: =+CONCATENATE(TEXT(AS51,"00"),TEXT(AT51,"00"),RIGHT(AU51,2)) -> 000100
... A487: =1+A483 -> 122 | E487: =+AQ487 | G487: =+AV487 -> 000100 | H487: =+AK487 -> 0 | I487: =+ROUND(AD487,2) -> 0 | K487: =+AE487 -> 0 | L487: =+AJ487 -> 0 | M487: 101 | P487: =+VLOOKUP(C487,Hoja1!$A$4:$C$57,3,FALSE) -> #N/A | Q487: 103 | S487: =(RIGHT(O487,7)) | U487: RC100 | V487: C001 | W487: =+AI487 -> 0 | X487: =+AJ487 -> 0 | Y487: 1 | Z487: =+F487 -> 0 | AC487: 0 | AD487: =+AB487+AC487 -> 0 | AF487: =+AB487*AE487 -> 0 | AG487: =+AC487*AE487 -> 0 | AH487: =+AD487*AE487 -> 0 | AI487: =+ROUND(AF487,2) -> 0 | AJ487: =+ROUND(AG487,2) -> 0 | AK487: =+ROUND(AH487,2) -> 0 | AL487: =+AI487+AJ487-AK487 -> 0 | AN487: =+LEFT(AM487,2) | AO487: =+MID(AM487,4,2) | AP487: =+RIGHT(AM487,2) | AQ487: =+CONCATENATE(AN487,AO487,AP487) | AR487: =AM487+_xlfn.XLOOKUP(C487,Hoja1!A:A,Hoja1!B:B) -> 0 | AS487: =+DAY(AR487) -> 0 | AT487: =+MONTH(AR487) -> 1 | AU487: =+YEAR(AR487) -> 1900 | AV487: =+CONCATENATE(TEXT(AS487,"00"),TEXT(AT487,"00"),RIGHT(AU487,2)) -> 000100

Sheet asiento conta
B1: cta | C1: cc | D1: linea | E1: nit | F1: TDW | G1: importe soles | H1: importe dol | I1: cod moneda | J1: glosa | K1: fecha | L1: nit cliente | M1: serie y correlatico | N1: cod trans
A2: =1 -> 1 | B2: =+'libro compras'!$AI$1 -> 281110 | C2: =+'libro compras'!Q3 -> 103 | D2: =+'libro compras'!R3 -> 0 | E2: =+'libro compras'!S3 | G2: =+'libro compras'!AK3 -> 0 | I2: 00 | J2: =+CONCATENATE('libro compras'!C3," ",'libro compras'!D3) | K2: =+'libro compras'!F3 -> 0 | L2: =+'libro compras'!C3 -> 0 | M2: =+'libro compras'!D3 -> 0 | N2: FC_LC
A3: =+A2 -> 1 | B3: =+'libro compras'!$AJ$1 -> 401110 | C3: =+C2 -> 103 | D3: =+D2 -> 0 | E3: =+E2 | G3: =+'libro compras'!AJ3 -> 0 | I3: 00 | J3: =+J2 | K3: =+K2 -> 0 | L3: =+L2 -> 0 | M3: =+M2 -> 0 | N3: FC_LC
A4: =+A2 -> 1 | B4: =+'libro compras'!P3 -> #N/A | C4: =+C3 -> 103 | D4: =+D3 -> 0 | E4: =+E3 | G4: =-'libro compras'!AI3 -> 0 | I4: 01 | J4: =+CONCATENATE('libro compras'!C3," ",'libro compras'!D3) | K4: =+K3 -> 0 | L4: =+L3 -> 0 | M4: =+M3 -> 0 | N4: FC_LC
A5: =+A4 -> 1 | B5: =+VLOOKUP(B4,Hoja1!$A$1:$B$2,2,FALSE) -> #N/A | C5: =+C4 -> 103 | D5: =+D4 -> 0 | E5: =+E4 | G5: =-'libro compras'!AB3 -> 0 | I5: 01 | J5: =+CONCATENATE('libro compras'!C3," ",'libro compras'!D3) | K5: =+K4 -> 0 | L5: =+L4 -> 0 | M5: =+M4 -> 0 | N5: FC_LC
A6: =1+A2 -> 2 | B6: =+'libro compras'!$AI$1 -> 281110 | C6: =+'libro compras'!Q7 -> 103 | D6: =+'libro compras'!R7 -> 0 | E6: =+'libro compras'!S7 | G6: =+'libro compras'!AK7 -> 0 | I6: 00 | J6: =+CONCATENATE('libro compras'!C7," ",'libro compras'!D7) | K6: =+'libro compras'!F7 -> 0 | L6: =+'libro compras'!C7 -> 0 | M6: =+'libro compras'!D7 -> 0 | N6: FC_LC
A7: =1+A3 -> 2 | B7: =+'libro compras'!$AJ$1 -> 401110 | C7: =+C6 -> 103 | D7: =+D6 -> 0 | E7: =+E6 | G7: =+'libro compras'!AJ7 -> 0 | I7: 00 | J7: =+J6 | K7: =+K6 -> 0 | L7: =+L6 -> 0 | M7: =+M6 -> 0 | N7: FC_LC
A8: =1+A4 -> 2 | B8: =+'libro compras'!P7 -> #N/A | C8: =+C7 -> 103 | D8: =+D7 -> 0 | E8: =+E7 | G8: =-'libro compras'!AI7 -> 0 | I8: 01 | J8: =+CONCATENATE('libro compras'!C7," ",'libro compras'!D7) | K8: =+K7 -> 0 | L8: =+L7 -> 0 | M8: =+M7 -> 0 | N8: FC_LC
A9: =1+A5 -> 2 | B9: =+VLOOKUP(B8,Hoja1!$A$1:$B$2,2,FALSE) -> #N/A | C9: =+C8 -> 103 | D9: =+D8 -> 0 | E9: =+E8 | G9: =-'libro compras'!AB7 -> 0 | I9: 01 | J9: =+CONCATENATE('libro compras'!C7," ",'libro compras'!D7) | K9: =+K8 -> 0 | L9: =+L8 -> 0 | M9: =+M8 -> 0 | N9: FC_LC
A10: =1+A6 -> 3 | B10: =+'libro compras'!$AI$1 -> 281110 | C10: =+'libro compras'!Q11 -> 103 | D10: =+'libro compras'!R11 -> 0 | E10: =+'libro compras'!S11 | G10: =+'libro compras'!AK11 -> 0 | I10: 00 | J10: =+CONCATENATE('libro compras'!C11," ",'libro compras'!D11) | K10: =+'libro compras'!F11 -> 0 | L10: =+'libro compras'!C11 -> 0 | M10: =+'libro compras'!D11 -> 0 | N10: FC_LC
A11: =1+A7 -> 3 | B11: =+'libro compras'!$AJ$1 -> 401110 | C11: =+C10 -> 103 | D11: =+D10 -> 0 | E11: =+E10 | G11: =+'libro compras'!AJ11 -> 0 | I11: 00 | J11: =+J10 | K11: =+K10 -> 0 | L11: =+L10 -> 0 | M11: =+M10 -> 0 | N11: FC_LC
A12: =1+A8 -> 3 | B12: =+'libro compras'!P11 -> #N/A | C12: =+C11 -> 103 | D12: =+D11 -> 0 | E12: =+E11 | G12: =-'libro compras'!AI11 -> 0 | I12: 01 | J12: =+CONCATENATE('libro compras'!C11," ",'libro compras'!D11) | K12: =+K11 -> 0 | L12: =+L11 -> 0 | M12: =+M11 -> 0 | N12: FC_LC
A13: =1+A9 -> 3 | B13: =+VLOOKUP(B12,Hoja1!$A$1:$B$2,2,FALSE) -> #N/A | C13: =+C12 -> 103 | D13: =+D12 -> 0 | E13: =+E12 | G13: =-'libro compras'!AB11 -> 0 | I13: 01 | J13: =+CONCATENATE('libro compras'!C11," ",'libro compras'!D11) | K13: =+K12 -> 0 | L13: =+L12 -> 0 | M13: =+M12 -> 0 | N13: FC_LC
A14: =1+A10 -> 4 | B14: =+'libro compras'!$AI$1 -> 281110 | C14: =+'libro compras'!Q15 -> 103 | D14: =+'libro compras'!R15 -> 0 | E14: =+'libro compras'!S15 | G14: =+'libro compras'!AK15 -> 0 | I14: 00 | J14: =+CONCATENATE('libro compras'!C15," ",'libro compras'!D15) | K14: =+'libro compras'!F15 -> 0 | L14: =+'libro compras'!C15 -> 0 | M14: =+'libro compras'!D15 -> 0 | N14: FC_LC
A15: =1+A11 -> 4 | B15: =+'libro compras'!$AJ$1 -> 401110 | C15: =+C14 -> 103 | D15: =+D14 -> 0 | E15: =+E14 | G15: =+'libro compras'!AJ15 -> 0 | I15: 00 | J15: =+J14 | K15: =+K14 -> 0 | L15: =+L14 -> 0 | M15: =+M14 -> 0 | N15: FC_LC
A16: =1+A12 -> 4 | B16: =+'libro compras'!P15 -> #N/A | C16: =+C15 -> 103 | D16: =+D15 -> 0 | E16: =+E15 | G16: =-'libro compras'!AI15 -> 0 | I16: 01 | J16: =+CONCATENATE('libro compras'!C15," ",'libro compras'!D15) | K16: =+K15 -> 0 | L16: =+L15 -> 0 | M16: =+M15 -> 0 | N16: FC_LC
A17: =1+A13 -> 4 | B17: =+VLOOKUP(B16,Hoja1!$A$1:$B$2,2,FALSE) -> #N/A | C17: =+C16 -> 103 | D17: =+D16 -> 0 | E17: =+E16 | G17: =-'libro compras'!AB15 -> 0 | I17: 01 | J17: =+CONCATENATE('libro compras'!C15," ",'libro compras'!D15) | K17: =+K16 -> 0 | L17: =+L16 -> 0 | M17: =+M16 -> 0 | N17: FC_LC
A18: =1+A14 -> 5 | B18: =+'libro compras'!$AI$1 -> 281110 | C18: =+'libro compras'!Q19 -> 103 | D18: =+'libro compras'!R19 -> 0 | E18: =+'libro compras'!S19 | G18: =+'libro compras'!AK19 -> 0 | I18: 00 | J18: =+CONCATENATE('libro compras'!C19," ",'libro compras'!D19) | K18: =+'libro compras'!F19 -> 0 | L18: =+'libro compras'!C19 -> 0 | M18: =+'libro compras'!D19 -> 0 | N18: FC_LC
A19: =1+A15 -> 5 | B19: =+'libro compras'!$AJ$1 -> 401110 | C19: =+C18 -> 103 | D19: =+D18 -> 0 | E19: =+E18 | G19: =+'libro compras'!AJ19 -> 0 | I19: 00 | J19: =+J18 | K19: =+K18 -> 0 | L19: =+L18 -> 0 | M19: =+M18 -> 0 | N19: FC_LC
A20: =1+A16 -> 5 | B20: =+'libro compras'!P19 -> #N/A | C20: =+C19 -> 103 | D20: =+D19 -> 0 | E20: =+E19 | G20: =-'libro compras'!AI19 -> 0 | I20: 01 | J20: =+CONCATENATE('libro compras'!C19," ",'libro compras'!D19) | K20: =+K19 -> 0 | L20: =+L19 -> 0 | M20: =+M19 -> 0 | N20: FC_LC
A21: =1+A17 -> 5 | B21: =+VLOOKUP(B20,Hoja1!$A$1:$B$2,2,FALSE) -> #N/A | C21: =+C20 -> 103 | D21: =+D20 -> 0 | E21: =+E20 | G21: =-'libro compras'!AB19 -> 0 | I21: 01 | J21: =+CONCATENATE('libro compras'!C19," ",'libro compras'!D19) | K21: =+K20 -> 0 | L21: =+L20 -> 0 | M21: =+M20 -> 0 | N21: FC_LC
A22: =1+A18 -> 6 | B22: =+'libro compras'!$AI$1 -> 281110 | C22: =+'libro compras'!Q23 -> 103 | D22: =+'libro compras'!R23 -> 0 | E22: =+'libro compras'!S23 | G22: =+'libro compras'!AK23 -> 0 | I22: 00 | J22: =+CONCATENATE('libro compras'!C23," ",'libro compras'!D23) | K22: =+'libro compras'!F23 -> 0 | L22: =+'libro compras'!C23 -> 0 | M22: =+'libro compras'!D23 -> 0 | N22: FC_LC
A23: =1+A19 -> 6 | B23: =+'libro compras'!$AJ$1 -> 401110 | C23: =+C22 -> 103 | D23: =+D22 -> 0 | E23: =+E22 | G23: =+'libro compras'!AJ23 -> 0 | I23: 00 | J23: =+J22 | K23: =+K22 -> 0 | L23: =+L22 -> 0 | M23: =+M22 -> 0 | N23: FC_LC
A24: =1+A20 -> 6 | B24: =+'libro compras'!P23 -> #N/A | C24: =+C23 -> 103 | D24: =+D23 -> 0 | E24: =+E23 | G24: =-'libro compras'!AI23 -> 0 | I24: 01 | J24: =+CONCATENATE('libro compras'!C23," ",'libro compras'!D23) | K24: =+K23 -> 0 | L24: =+L23 -> 0 | M24: =+M23 -> 0 | N24: FC_LC
A25: =1+A21 -> 6 | B25: =+VLOOKUP(B24,Hoja1!$A$1:$B$2,2,FALSE) -> #N/A | C25: =+C24 -> 103 | D25: =+D24 -> 0 | E25: =+E24 | G25: =-'libro compras'!AB23 -> 0 | I25: 01 | J25: =+CONCATENATE('libro compras'!C23," ",'libro compras'!D23) | K25: =+K24 -> 0 | L25: =+L24 -> 0 | M25: =+M24 -> 0 | N25: FC_LC
A26: =1+A22 -> 7 | B26: =+'libro compras'!$AI$1 -> 281110 | C26: =+'libro compras'!Q27 -> 103 | D26: =+'libro compras'!R27 -> 0 | E26: =+'libro compras'!S27 | G26: =+'libro compras'!AK27 -> 0 | I26: 00 | J26: =+CONCATENATE('libro compras'!C27," ",'libro compras'!D27) | K26: =+'libro compras'!F27 -> 0 | L26: =+'libro compras'!C27 -> 0 | M26: =+'libro compras'!D27 -> 0 | N26: FC_LC
A27: =1+A23 -> 7 | B27: =+'libro compras'!$AJ$1 -> 401110 | C27: =+C26 -> 103 | D27: =+D26 -> 0 | E27: =+E26 | G27: =+'libro compras'!AJ27 -> 0 | I27: 00 | J27: =+J26 | K27: =+K26 -> 0 | L27: =+L26 -> 0 | M27: =+M26 -> 0 | N27: FC_LC
A28: =1+A24 -> 7 | B28: =+'libro compras'!P27 -> #N/A | C28: =+C27 -> 103 | D28: =+D27 -> 0 | E28: =+E27 | G28: =-'libro compras'!AI27 -> 0 | I28: 01 | J28: =+CONCATENATE('libro compras'!C27," ",'libro compras'!D27) | K28: =+K27 -> 0 | L28: =+L27 -> 0 | M28: =+M27 -> 0 | N28: FC_LC
A29: =1+A25 -> 7 | B29: =+VLOOKUP(B28,Hoja1!$A$1:$B$2,2,FALSE) -> #N/A | C29: =+C28 -> 103 | D29: =+D28 -> 0 | E29: =+E28 | G29: =-'libro compras'!AB27 -> 0 | I29: 01 | J29: =+CONCATENATE('libro compras'!C27," ",'libro compras'!D27) | K29: =+K28 -> 0 | L29: =+L28 -> 0 | M29: =+M28 -> 0 | N29: FC_LC
A30: =1+A26 -> 8 | B30: =+'libro compras'!$AI$1 -> 281110 | C30: =+'libro compras'!Q31 -> 103 | D30: =+'libro compras'!R31 -> 0 | E30: =+'libro compras'!S31 | G30: =+'libro compras'!AK31 -> 0 | I30: 00 | J30: =+CONCATENATE('libro compras'!C31," ",'libro compras'!D31) | K30: =+'libro compras'!F31 -> 0 | L30: =+'libro compras'!C31 -> 0 | M30: =+'libro compras'!D31 -> 0 | N30: FC_LC
A31: =1+A27 -> 8 | B31: =+'libro compras'!$AJ$1 -> 401110 | C31: =+C30 -> 103 | D31: =+D30 -> 0 | E31: =+E30 | G31: =+'libro compras'!AJ31 -> 0 | I31: 00 | J31: =+J30 | K31: =+K30 -> 0 | L31: =+L30 -> 0 | M31: =+M30 -> 0 | N31: FC_LC
A32: =1+A28 -> 8 | B32: =+'libro compras'!P31 -> #N/A | C32: =+C31 -> 103 | D32: =+D31 -> 0 | E32: =+E31 | G32: =-'libro compras'!AI31 -> 0 | I32: 01 | J32: =+CONCATENATE('libro compras'!C31," ",'libro compras'!D31) | K32: =+K31 -> 0 | L32: =+L31 -> 0 | M32: =+M31 -> 0 | N32: FC_LC
A33: =1+A29 -> 8 | B33: =+VLOOKUP(B32,Hoja1!$A$1:$B$2,2,FALSE) -> #N/A | C33: =+C32 -> 103 | D33: =+D32 -> 0 | E33: =+E32 | G33: =-'libro compras'!AB31 -> 0 | I33: 01 | J33: =+CONCATENATE('libro compras'!C31," ",'libro compras'!D31) | K33: =+K32 -> 0 | L33: =+L32 -> 0 | M33: =+M32 -> 0 | N33: FC_LC
A34: =1+A30 -> 9 | B34: =+'libro compras'!$AI$1 -> 281110 | C34: =+'libro compras'!Q35 -> 103 | D34: =+'libro compras'!R35 -> 0 | E34: =+'libro compras'!S35 | G34: =+'libro compras'!AK35 -> 0 | I34: 00 | J34: =+CONCATENATE('libro compras'!C35," ",'libro compras'!D35) | K34: =+'libro compras'!F35 -> 0 | L34: =+'libro compras'!C35 -> 0 | M34: =+'libro compras'!D35 -> 0 | N34: FC_LC
A35: =1+A31 -> 9 | B35: =+'libro compras'!$AJ$1 -> 401110 | C35: =+C34 -> 103 | D35: =+D34 -> 0 | E35: =+E34 | G35: =+'libro compras'!AJ35 -> 0 | I35: 00 | J35: =+J34 | K35: =+K34 -> 0 | L35: =+L34 -> 0 | M35: =+M34 -> 0 | N35: FC_LC
A36: =1+A32 -> 9 | B36: =+'libro compras'!P35 -> #N/A | C36: =+C35 -> 103 | D36: =+D35 -> 0 | E36: =+E35 | G36: =-'libro compras'!AI35 -> 0 | I36: 01 | J36: =+CONCATENATE('libro compras'!C35," ",'libro compras'!D35) | K36: =+K35 -> 0 | L36: =+L35 -> 0 | M36: =+M35 -> 0 | N36: FC_LC
A37: =1+A33 -> 9 | B37: =+VLOOKUP(B36,Hoja1!$A$1:$B$2,2,FALSE) -> #N/A | C37: =+C36 -> 103 | D37: =+D36 -> 0 | E37: =+E36 | G37: =-'libro compras'!AB35 -> 0 | I37: 01 | J37: =+CONCATENATE('libro compras'!C35," ",'libro compras'!D35) | K37: =+K36 -> 0 | L37: =+L36 -> 0 | M37: =+M36 -> 0 | N37: FC_LC
A38: =1+A34 -> 10 | B38: =+'libro compras'!$AI$1 -> 281110 | C38: =+'libro compras'!Q39 -> 103 | D38: =+'libro compras'!R39 -> 0 | E38: =+'libro compras'!S39 | G38: =+'libro compras'!AK39 -> 0 | I38: 00 | J38: =+CONCATENATE('libro compras'!C39," ",'libro compras'!D39) | K38: =+'libro compras'!F39 -> 0 | L38: =+'libro compras'!C39 -> 0 | M38: =+'libro compras'!D39 -> 0 | N38: FC_LC
A39: =1+A35 -> 10 | B39: =+'libro compras'!$AJ$1 -> 401110 | C39: =+C38 -> 103 | D39: =+D38 -> 0 | E39: =+E38 | G39: =+'libro compras'!AJ39 -> 0 | I39: 00 | J39: =+J38 | K39: =+K38 -> 0 | L39: =+L38 -> 0 | M39: =+M38 -> 0 | N39: FC_LC
A40: =1+A36 -> 10 | B40: =+'libro compras'!P39 -> #N/A | C40: =+C39 -> 103 | D40: =+D39 -> 0 | E40: =+E39 | G40: =-'libro compras'!AI39 -> 0 | I40: 01 | J40: =+CONCATENATE('libro compras'!C39," ",'libro compras'!D39) | K40: =+K39 -> 0 | L40: =+L39 -> 0 | M40: =+M39 -> 0 | N40: FC_LC
...

Sheet Hoja1
A1: 431202 | B1: 0136
A2: 421203 | B2: 0132
A4: SEI | B4: 45 | C4: 431202
A5: 51092775 | B5: 13 | C5: 421201
A6: 7DQ | B6: 180 | C6: 421203
A7: 5BE | B7: 180 | C7: 421203
A8: US1239 | B8: 45 | C8: 431202
A9: 5EX | B9: 90 | C9: 421203
A10: GEODIS | B10: 30 | C10: 421203
A11: 5NN | B11: 75 | C11: 421203
A12: 5JU | B12: 120 | C12: 421203
A13: SNOWKY | B13: 180 | C13: 421203
A14: 5KW | B14: 60 | C14: 421203
A15: CNV | B15: 45 | C15: 431202
... A30: COA | B30: 45 | C30: 431202

Sheet Hoja2
A1: CADENA DE CONT
A2: 0232025
A3: 0242025
A4: 0252025
A5: 0262025
A6: 2024680
A7: 2024682
A8: 2024683
A9: 2024684
A10: 2024685
A11: 2024687
A12: 2024688
... A45: 2025409
