Workbook

Sheet libro compras
H1: S/. | I1: $ | K1: =+I3*K3 -> 0 | N1: TIPO DOC SUNAT | T1: TIPO DOC ISCALA | AB1: 0131 | AK1: 281110 | AL1: 401110 | AN1: 421202
A2: SEQ | B2: ASSIENTO | C2: COD PRVEEDOR | D2: NUMERO DE FACTURA | E2: FECHA FACT | F2: FECHA CONT | G2: FECHA VENC | H2: Importe Facturado | I2: Importe Facturado Org | J2: COD MONEDA | K2: Tipo de cambio | L2: IVA | M2: Código Banco Central | N2: Cód. de Autorización | O2: Comentarios | P2: CADENA DE CONT | Q2: CADENA DE CONT | R2: CADENA DE CONT | S2: CADENA DE CONT | T2: TIPO DE FACTURA | U2: CODIGO CARGA FISCAL | V2: Tipo IVA Código impuest | W2: Base imponible Registro impues | X2: Importe IVA Código impuest | Y2: Tipo IVA Registro impuest | Z2: Fecha Transacción Registro Impues | AB2: V.V | AC2: IGV | AD2: ADD | AE2: P.V | AF2: TC | AG2: V.V | AH2: IGV | AI2: ADD | AJ2: P.V | AK2: V.V | AL2: IGV | AM2: ADD | AN2: P.V | AO2: DIFERENCIA
A3: 1 | G3: =+E3 -> 0 | H3: =+AL3+AM3 -> 0 | I3: =+AC3+AD3 -> 0 | K3: =+AF3 -> 0 | L3: =+AL3 -> 0 | M3: 101 | Q3: 103 | S3: =(RIGHT(O3,7)) | U3: RC005 | V3: C001 | W3: =+AK3 -> 0 | X3: =+AL3 -> 0 | Y3: 1 | Z3: =+E3 -> 0 | AB3: =(AC3*100)/18 -> 0 | AE3: =+AB3+AC3+AD3 -> 0 | AG3: =+AB3*AF3 -> 0 | AH3: =+AC3*AF3 -> 0 | AI3: =+AD3*AF3 -> 0 | AJ3: =+AE3*AF3 -> 0 | AK3: =+ROUND(AG3,2) -> 0 | AL3: =+ROUND(AH3,2) -> 0 | AM3: =+ROUND(AI3,2) -> 0 | AN3: =+ROUND(AJ3,2) -> 0 | AO3: =+AK3+AL3-AN3+AM3 -> 0
A7: =1+A3 -> 2 | G7: =+E7 -> 0 | H7: =+AL7+AM7 -> 0 | I7: =+AC7+AD7 -> 0 | K7: =+AF7 -> 0 | L7: =+AL7 -> 0 | M7: 101 | Q7: 103 | S7: =(RIGHT(O7,7)) | U7: RC005 | V7: C001 | W7: =+AK7 -> 0 | X7: =+AL7 -> 0 | Y7: 1 | Z7: =+G7 -> 0 | AB7: =(AC7*100)/18 -> 0 | AE7: =+AB7+AC7+AD7 -> 0 | AG7: =+AB7*AF7 -> 0 | AH7: =+AC7*AF7 -> 0 | AI7: =+AD7*AF7 -> 0 | AJ7: =+AE7*AF7 -> 0 | AK7: =+ROUND(AG7,2) -> 0 | AL7: =+ROUND(AH7,2) -> 0 | AM7: =+ROUND(AI7,2) -> 0 | AN7: =+ROUND(AJ7,2) -> 0 | AO7: =+AK7+AL7-AN7+AM7 -> 0
A11: =1+A7 -> 3 | G11: =+E11 -> 0 | H11: =+AL11+AM11 -> 0 | I11: =+AC11+AD11 -> 0 | K11: =+AF11 -> 0 | L11: =+AL11 -> 0 | M11: 101 | Q11: 103 | S11: =(RIGHT(O11,7)) | U11: RC005 | V11: C001 | W11: =+AK11 -> 0 | X11: =+AL11 -> 0 | Y11: 1 | Z11: =+G11 -> 0 | AB11: =(AC11*100)/18 -> 0 | AE11: =+AB11+AC11+AD11 -> 0 | AG11: =+AB11*AF11 -> 0 | AH11: =+AC11*AF11 -> 0 | AI11: =+AD11*AF11 -> 0 | AJ11: =+AE11*AF11 -> 0 | AK11: =+ROUND(AG11,2) -> 0 | AL11: =+ROUND(AH11,2) -> 0 | AM11: =+ROUND(AI11,2) -> 0 | AN11: =+ROUND(AJ11,2) -> 0 | AO11: =+AK11+AL11-AN11+AM11 -> 0
A15: =1+A11 -> 4 | G15: =+E15 -> 0 | H15: =+AL15+AM15 -> 0 | I15: =+AC15+AD15 -> 0 | K15: =+AF15 -> 0 | L15: =+AL15 -> 0 | M15: 101 | Q15: 103 | S15: =(RIGHT(O15,7)) | U15: RC005 | V15: C001 | W15: =+AK15 -> 0 | X15: =+AL15 -> 0 | Y15: 1 | Z15: =+G15 -> 0 | AB15: =(AC15*100)/18 -> 0 | AE15: =+AB15+AC15+AD15 -> 0 | AG15: =+AB15*AF15 -> 0 | AH15: =+AC15*AF15 -> 0 | AI15: =+AD15*AF15 -> 0 | AJ15: =+AE15*AF15 -> 0 | AK15: =+ROUND(AG15,2) -> 0 | AL15: =+ROUND(AH15,2) -> 0 | AM15: =+ROUND(AI15,2) -> 0 | AN15: =+ROUND(AJ15,2) -> 0 | AO15: =+AK15+AL15-AN15+AM15 -> 0
A19: =1+A15 -> 5 | G19: =+E19 -> 0 | H19: =+AL19+AM19 -> 0 | I19: =+AC19+AD19 -> 0 | K19: =+AF19 -> 0 | L19: =+AL19 -> 0 | M19: 101 | Q19: 103 | S19: =(RIGHT(O19,7)) | U19: RC005 | V19: C001 | W19: =+AK19 -> 0 | X19: =+AL19 -> 0 | Y19: 1 | Z19: =+G19 -> 0 | AB19: =(AC19*100)/18 -> 0 | AE19: =+AB19+AC19+AD19 -> 0 | AG19: =+AB19*AF19 -> 0 | AH19: =+AC19*AF19 -> 0 | AI19: =+AD19*AF19 -> 0 | AJ19: =+AE19*AF19 -> 0 | AK19: =+ROUND(AG19,2) -> 0 | AL19: =+ROUND(AH19,2) -> 0 | AM19: =+ROUND(AI19,2) -> 0 | AN19: =+ROUND(AJ19,2) -> 0 | AO19: =+AK19+AL19-AN19+AM19 -> 0
A23: =1+A19 -> 6 | G23: =+E23 -> 0 | H23: =+AL23+AM23 -> 0 | I23: =+AC23+AD23 -> 0 | K23: =+AF23 -> 0 | L23: =+AL23 -> 0 | M23: 101 | Q23: 103 | S23: =(RIGHT(O23,7)) | U23: RC005 | V23: C001 | W23: =+AK23 -> 0 | X23: =+AL23 -> 0 | Y23: 1 | Z23: =+G23 -> 0 | AB23: =(AC23*100)/18 -> 0 | AE23: =+AB23+AC23+AD23 -> 0 | AG23: =+AB23*AF23 -> 0 | AH23: =+AC23*AF23 -> 0 | AI23: =+AD23*AF23 -> 0 | AJ23: =+AE23*AF23 -> 0 | AK23: =+ROUND(AG23,2) -> 0 | AL23: =+ROUND(AH23,2) -> 0 | AM23: =+ROUND(AI23,2) -> 0 | AN23: =+ROUND(AJ23,2) -> 0 | AO23: =+AK23+AL23-AN23+AM23 -> 0
A27: =1+A23 -> 7 | G27: =+E27 -> 0 | H27: =+AL27+AM27 -> 0 | I27: =+AC27+AD27 -> 0 | K27: =+AF27 -> 0 | L27: =+AL27 -> 0 | M27: 101 | Q27: 103 | S27: =(RIGHT(O27,7)) | U27: RC005 | V27: C001 | W27: =+AK27 -> 0 | X27: =+AL27 -> 0 | Y27: 1 | Z27: =+G27 -> 0 | AB27: =(AC27*100)/18 -> 0 | AE27: =+AB27+AC27+AD27 -> 0 | AG27: =+AB27*AF27 -> 0 | AH27: =+AC27*AF27 -> 0 | AI27: =+AD27*AF27 -> 0 | AJ27: =+AE27*AF27 -> 0 | AK27: =+ROUND(AG27,2) -> 0 | AL27: =+ROUND(AH27,2) -> 0 | AM27: =+ROUND(AI27,2) -> 0 | AN27: =+ROUND(AJ27,2) -> 0 | AO27: =+AK27+AL27-AN27+AM27 -> 0
A31: =1+A27 -> 8 | G31: =+E31 -> 0 | H31: =+AL31+AM31 -> 0 | I31: =+AC31+AD31 -> 0 | K31: =+AF31 -> 0 | L31: =+AL31 -> 0 | M31: 101 | Q31: 103 | S31: =(RIGHT(O31,7)) | U31: RC005 | V31: C001 | W31: =+AK31 -> 0 | X31: =+AL31 -> 0 | Y31: 1 | Z31: =+G31 -> 0 | AB31: =(AC31*100)/18 -> 0 | AE31: =+AB31+AC31+AD31 -> 0 | AG31: =+AB31*AF31 -> 0 | AH31: =+AC31*AF31 -> 0 | AI31: =+AD31*AF31 -> 0 | AJ31: =+AE31*AF31 -> 0 | AK31: =+ROUND(AG31,2) -> 0 | AL31: =+ROUND(AH31,2) -> 0 | AM31: =+ROUND(AI31,2) -> 0 | AN31: =+ROUND(AJ31,2) -> 0 | AO31: =+AK31+AL31-AN31+AM31 -> 0
A35: =1+A31 -> 9 | G35: =+E35 -> 0 | H35: =+AL35+AM35 -> 0 | I35: =+AC35+AD35 -> 0 | K35: =+AF35 -> 0 | L35: =+AL35 -> 0 | M35: 101 | Q35: 103 | S35: =(RIGHT(O35,7)) | U35: RC005 | V35: C001 | W35: =+AK35 -> 0 | X35: =+AL35 -> 0 | Y35: 1 | Z35: =+G35 -> 0 | AB35: =(AC35*100)/18 -> 0 | AE35: =+AB35+AC35+AD35 -> 0 | AG35: =+AB35*AF35 -> 0 | AH35: =+AC35*AF35 -> 0 | AI35: =+AD35*AF35 -> 0 | AJ35: =+AE35*AF35 -> 0 | AK35: =+ROUND(AG35,2) -> 0 | AL35: =+ROUND(AH35,2) -> 0 | AM35: =+ROUND(AI35,2) -> 0 | AN35: =+ROUND(AJ35,2) -> 0 | AO35: =+AK35+AL35-AN35+AM35 -> 0
A39: =1+A35 -> 10 | G39: =+E39 -> 0 | H39: =+AL39+AM39 -> 0 | I39: =+AC39+AD39 -> 0 | K39: =+AF39 -> 0 | L39: =+AL39 -> 0 | M39: 101 | Q39: 103 | S39: =(RIGHT(O39,7)) | U39: RC005 | V39: C001 | W39: =+AK39 -> 0 | X39: =+AL39 -> 0 | Y39: 1 | Z39: =+G39 -> 0 | AB39: =(AC39*100)/18 -> 0 | AE39: =+AB39+AC39+AD39 -> 0 | AG39: =+AB39*AF39 -> 0 | AH39: =+AC39*AF39 -> 0 | AI39: =+AD39*AF39 -> 0 | AJ39: =+AE39*AF39 -> 0 | AK39: =+ROUND(AG39,2) -> 0 | AL39: =+ROUND(AH39,2) -> 0 | AM39: =+ROUND(AI39,2) -> 0 | AN39: =+ROUND(AJ39,2) -> 0 | AO39: =+AK39+AL39-AN39+AM39 -> 0
A43: =1+A39 -> 11 | G43: =+E43 -> 0 | H43: =+AL43+AM43 -> 0 | I43: =+AC43+AD43 -> 0 | K43: =+AF43 -> 0 | L43: =+AL43 -> 0 | M43: 101 | Q43: 103 | S43: =(RIGHT(O43,7)) | U43: RC005 | V43: C001 | W43: =+AK43 -> 0 | X43: =+AL43 -> 0 | Y43: 1 | Z43: =+G43 -> 0 | AB43: =(AC43*100)/18 -> 0 | AE43: =+AB43+AC43+AD43 -> 0 | AG43: =+AB43*AF43 -> 0 | AH43: =+AC43*AF43 -> 0 | AI43: =+AD43*AF43 -> 0 | AJ43: =+AE43*AF43 -> 0 | AK43: =+ROUND(AG43,2) -> 0 | AL43: =+ROUND(AH43,2) -> 0 | AM43: =+ROUND(AI43,2) -> 0 | AN43: =+ROUND(AJ43,2) -> 0 | AO43: =+AK43+AL43-AN43+AM43 -> 0
A47: =1+A43 -> 12 | G47: =+E47 -> 0 | H47: =+AL47+AM47 -> 0 | I47: =+AC47+AD47 -> 0 | K47: =+AF47 -> 0 | L47: =+AL47 -> 0 | M47: 101 | Q47: 103 | S47: =(RIGHT(O47,7)) | U47: RC005 | V47: C001 | W47: =+AK47 -> 0 | X47: =+AL47 -> 0 | Y47: 1 | Z47: =+G47 -> 0 | AB47: =(AC47*100)/18 -> 0 | AE47: =+AB47+AC47+AD47 -> 0 | AG47: =+AB47*AF47 -> 0 | AH47: =+AC47*AF47 -> 0 | AI47: =+AD47*AF47 -> 0 | AJ47: =+AE47*AF47 -> 0 | AK47: =+ROUND(AG47,2) -> 0 | AL47: =+ROUND(AH47,2) -> 0 | AM47: =+ROUND(AI47,2) -> 0 | AN47: =+ROUND(AJ47,2) -> 0 | AO47: =+AK47+AL47-AN47+AM47 -> 0
A51: =1+A47 -> 13 | G51: =+E51 -> 0 | H51: =+AL51+AM51 -> 0 | I51: =+AC51+AD51 -> 0 | K51: =+AF51 -> 0 | L51: =+AL51 -> 0 | M51: 101 | Q51: 103 | S51: =(RIGHT(O51,7)) | U51: RC005 | V51: C001 | W51: =+AK51 -> 0 | X51: =+AL51 -> 0 | Y51: 1 | Z51: =+G51 -> 0 | AB51: =(AC51*100)/18 -> 0 | AE51: =+AB51+AC51+AD51 -> 0 | AG51: =+AB51*AF51 -> 0 | AH51: =+AC51*AF51 -> 0 | AI51: =+AD51*AF51 -> 0 | AJ51: =+AE51*AF51 -> 0 | AK51: =+ROUND(AG51,2) -> 0 | AL51: =+ROUND(AH51,2) -> 0 | AM51: =+ROUND(AI51,2) -> 0 | AN51: =+ROUND(AJ51,2) -> 0 | AO51: =+AK51+AL51-AN51+AM51 -> 0
... A179: =1+A175 -> 45 | G179: =+E179 -> 0 | H179: =+AL179+AM179 -> 0 | I179: =+AC179+AD179 -> 0 | K179: =+AF179 -> 0 | L179: =+AL179 -> 0 | M179: 101 | Q179: 103 | S179: =(RIGHT(O179,7)) | U179: RC005 | V179: C001 | W179: =+AK179 -> 0 | X179: =+AL179 -> 0 | Y179: 1 | Z179: =+G179 -> 0 | AB179: =(AC179*100)/18 -> 0 | AE179: =+AB179+AC179+AD179 -> 0 | AG179: =+AB179*AF179 -> 0 | AH179: =+AC179*AF179 -> 0 | AI179: =+AD179*AF179 -> 0 | AJ179: =+AE179*AF179 -> 0 | AK179: =+ROUND(AG179,2) -> 0 | AL179: =+ROUND(AH179,2) -> 0 | AM179: =+ROUND(AI179,2) -> 0 | AN179: =+ROUND(AJ179,2) -> 0 | AO179: =+AK179+AL179-AN179+AM179 -> 0

Sheet asiento conta
B1: cta | C1: cc | D1: linea | E1: nit | F1: TDW | G1: importe soles | H1: importe dol | I1: cod moneda | J1: glosa | K1: fecha | L1: nit cliente | M1: serie y correlatico | N1: cod trans
A2: 1 | B2: =+'libro compras'!$AK$1 -> 281110 | C2: =+'libro compras'!Q3 -> 103 | E2: =+'libro compras'!S3 | G2: =+'libro compras'!AM3 -> 0 | I2: 00 | J2: =+CONCATENATE('libro compras'!C3," ",'libro compras'!D3) | K2: =+'libro compras'!F3 -> 0 | L2: =+'libro compras'!C3 -> 0 | M2: =+'libro compras'!D3 -> 0 | N2: FC_LC
A3: 1 | B3: =+'libro compras'!$AL$1 -> 401110 | C3: =+C2 -> 103 | E3: =+E2 | G3: =+'libro compras'!L3 -> 0 | I3: 00 | J3: =+J2 | K3: =+K2 -> 0 | L3: =+L2 -> 0 | M3: =+M2 -> 0 | N3: FC_LC
A4: 1 | B4: =+'libro compras'!$AN$1 -> 421202 | C4: =+C3 -> 103 | E4: =+E3 | G4: =-'libro compras'!H3 -> 0 | I4: 01 | J4: =+J3 | K4: =+K3 -> 0 | L4: =+L3 -> 0 | M4: =+M3 -> 0 | N4: FC_LC
A5: 1 | B5: =+'libro compras'!$AB$1 -> 0131 | C5: =+C4 -> 103 | E5: =+E4 | G5: =-'libro compras'!I3 -> 0 | I5: 01 | J5: =+J4 | K5: =+K4 -> 0 | L5: =+L4 -> 0 | M5: =+M4 -> 0 | N5: FC_LC
A6: =+A2+1 -> 2 | B6: =+'libro compras'!$AK$1 -> 281110 | C6: =+'libro compras'!Q7 -> 103 | E6: =+'libro compras'!S7 | G6: =+'libro compras'!AM7 -> 0 | I6: 00 | J6: =+CONCATENATE('libro compras'!C7," ",'libro compras'!D7) | K6: =+'libro compras'!F7 -> 0 | L6: =+'libro compras'!C7 -> 0 | M6: =+'libro compras'!D7 -> 0 | N6: FC_LC
A7: =+A6 -> 2 | B7: =+'libro compras'!$AL$1 -> 401110 | C7: =+C6 -> 103 | E7: =+E6 | G7: =+'libro compras'!L7 -> 0 | I7: 00 | J7: =+J6 | K7: =+K6 -> 0 | L7: =+L6 -> 0 | M7: =+M6 -> 0 | N7: FC_LC
A8: =+A7 -> 2 | B8: =+'libro compras'!$AN$1 -> 421202 | C8: =+C7 -> 103 | E8: =+E7 | G8: =-'libro compras'!H7 -> 0 | I8: 01 | J8: =+J7 | K8: =+K7 -> 0 | L8: =+L7 -> 0 | M8: =+M7 -> 0 | N8: FC_LC
A9: =+A8 -> 2 | B9: =+'libro compras'!$AB$1 -> 0131 | C9: =+C8 -> 103 | E9: =+E8 | G9: =-'libro compras'!I7 -> 0 | I9: 01 | J9: =+J8 | K9: =+K8 -> 0 | L9: =+L8 -> 0 | M9: =+M8 -> 0 | N9: FC_LC
A10: =1+A6 -> 3 | B10: =+'libro compras'!$AK$1 -> 281110 | C10: =+'libro compras'!Q11 -> 103 | E10: =+'libro compras'!S11 | G10: =+'libro compras'!AM11 -> 0 | I10: 00 | J10: =+CONCATENATE('libro compras'!C11," ",'libro compras'!D11) | K10: =+'libro compras'!F11 -> 0 | L10: =+'libro compras'!C11 -> 0 | M10: =+'libro compras'!D11 -> 0 | N10: FC_LC
A11: =+A10 -> 3 | B11: =+'libro compras'!$AL$1 -> 401110 | C11: =+C10 -> 103 | E11: =+E10 | G11: =+'libro compras'!L11 -> 0 | I11: 00 | J11: =+J10 | K11: =+K10 -> 0 | L11: =+L10 -> 0 | M11: =+M10 -> 0 | N11: FC_LC
A12: =+A11 -> 3 | B12: =+'libro compras'!$AN$1 -> 421202 | C12: =+C11 -> 103 | E12: =+E11 | G12: =-'libro compras'!H11 -> 0 | I12: 01 | J12: =+J11 | K12: =+K11 -> 0 | L12: =+L11 -> 0 | M12: =+M11 -> 0 | N12: FC_LC
A13: =+A12 -> 3 | B13: =+'libro compras'!$AB$1 -> 0131 | C13: =+C12 -> 103 | E13: =+E12 | G13: =-'libro compras'!I11 -> 0 | I13: 01 | J13: =+J12 | K13: =+K12 -> 0 | L13: =+L12 -> 0 | M13: =+M12 -> 0 | N13: FC_LC
A14: =1+A10 -> 4 | B14: =+'libro compras'!$AK$1 -> 281110 | C14: =+'libro compras'!Q15 -> 103 | E14: =+'libro compras'!S15 | G14: =+'libro compras'!AM15 -> 0 | I14: 00 | J14: =+CONCATENATE('libro compras'!C15," ",'libro compras'!D15) | K14: =+'libro compras'!F15 -> 0 | L14: =+'libro compras'!C15 -> 0 | M14: =+'libro compras'!D15 -> 0 | N14: FC_LC
A15: =+A14 -> 4 | B15: =+'libro compras'!$AL$1 -> 401110 | C15: =+C14 -> 103 | E15: =+E14 | G15: =+'libro compras'!L15 -> 0 | I15: 00 | J15: =+J14 | K15: =+K14 -> 0 | L15: =+L14 -> 0 | M15: =+M14 -> 0 | N15: FC_LC
A16: =+A15 -> 4 | B16: =+'libro compras'!$AN$1 -> 421202 | C16: =+C15 -> 103 | E16: =+E15 | G16: =-'libro compras'!H15 -> 0 | I16: 01 | J16: =+J15 | K16: =+K15 -> 0 | L16: =+L15 -> 0 | M16: =+M15 -> 0 | N16: FC_LC
A17: =+A16 -> 4 | B17: =+'libro compras'!$AB$1 -> 0131 | C17: =+C16 -> 103 | E17: =+E16 | G17: =-'libro compras'!I15 -> 0 | I17: 01 | J17: =+J16 | K17: =+K16 -> 0 | L17: =+L16 -> 0 | M17: =+M16 -> 0 | N17: FC_LC
A18: =1+A14 -> 5 | B18: =+'libro compras'!$AK$1 -> 281110 | C18: =+'libro compras'!Q19 -> 103 | E18: =+'libro compras'!S19 | G18: =+'libro compras'!AM19 -> 0 | I18: 00 | J18: =+CONCATENATE('libro compras'!C19," ",'libro compras'!D19) | K18: =+'libro compras'!F19 -> 0 | L18: =+'libro compras'!C19 -> 0 | M18: =+'libro compras'!D19 -> 0 | N18: FC_LC
A19: =+A18 -> 5 | B19: =+'libro compras'!$AL$1 -> 401110 | C19: =+C18 -> 103 | E19: =+E18 | G19: =+'libro compras'!L19 -> 0 | I19: 00 | J19: =+J18 | K19: =+K18 -> 0 | L19: =+L18 -> 0 | M19: =+M18 -> 0 | N19: FC_LC
A20: =+A19 -> 5 | B20: =+'libro compras'!$AN$1 -> 421202 | C20: =+C19 -> 103 | E20: =+E19 | G20: =-'libro compras'!H19 -> 0 | I20: 01 | J20: =+J19 | K20: =+K19 -> 0 | L20: =+L19 -> 0 | M20: =+M19 -> 0 | N20: FC_LC
A21: =+A20 -> 5 | B21: =+'libro compras'!$AB$1 -> 0131 | C21: =+C20 -> 103 | E21: =+E20 | G21: =-'libro compras'!I19 -> 0 | I21: 01 | J21: =+J20 | K21: =+K20 -> 0 | L21: =+L20 -> 0 | M21: =+M20 -> 0 | N21: FC_LC
A22: =1+A18 -> 6 | B22: =+'libro compras'!$AK$1 -> 281110 | C22: =+'libro compras'!Q23 -> 103 | E22: =+'libro compras'!S23 | G22: =+'libro compras'!AM23 -> 0 | I22: 00 | J22: =+CONCATENATE('libro compras'!C23," ",'libro compras'!D23) | K22: =+'libro compras'!F23 -> 0 | L22: =+'libro compras'!C23 -> 0 | M22: =+'libro compras'!D23 -> 0 | N22: FC_LC
A23: =+A22 -> 6 | B23: =+'libro compras'!$AL$1 -> 401110 | C23: =+C22 -> 103 | E23: =+E22 | G23: =+'libro compras'!L23 -> 0 | I23: 00 | J23: =+J22 | K23: =+K22 -> 0 | L23: =+L22 -> 0 | M23: =+M22 -> 0 | N23: FC_LC
A24: =+A23 -> 6 | B24: =+'libro compras'!$AN$1 -> 421202 | C24: =+C23 -> 103 | E24: =+E23 | G24: =-'libro compras'!H23 -> 0 | I24: 01 | J24: =+J23 | K24: =+K23 -> 0 | L24: =+L23 -> 0 | M24: =+M23 -> 0 | N24: FC_LC
A25: =+A24 -> 6 | B25: =+'libro compras'!$AB$1 -> 0131 | C25: =+C24 -> 103 | E25: =+E24 | G25: =-'libro compras'!I23 -> 0 | I25: 01 | J25: =+J24 | K25: =+K24 -> 0 | L25: =+L24 -> 0 | M25: =+M24 -> 0 | N25: FC_LC
A26: =1+A22 -> 7 | B26: =+'libro compras'!$AK$1 -> 281110 | C26: =+'libro compras'!Q27 -> 103 | E26: =+'libro compras'!S27 | G26: =+'libro compras'!AM27 -> 0 | I26: 00 | J26: =+CONCATENATE('libro compras'!C27," ",'libro compras'!D27) | K26: =+'libro compras'!F27 -> 0 | L26: =+'libro compras'!C27 -> 0 | M26: =+'libro compras'!D27 -> 0 | N26: FC_LC
A27: =+A26 -> 7 | B27: =+'libro compras'!$AL$1 -> 401110 | C27: =+C26 -> 103 | E27: =+E26 | G27: =+'libro compras'!L27 -> 0 | I27: 00 | J27: =+J26 | K27: =+K26 -> 0 | L27: =+L26 -> 0 | M27: =+M26 -> 0 | N27: FC_LC
A28: =+A27 -> 7 | B28: =+'libro compras'!$AN$1 -> 421202 | C28: =+C27 -> 103 | E28: =+E27 | G28: =-'libro compras'!H27 -> 0 | I28: 01 | J28: =+J27 | K28: =+K27 -> 0 | L28: =+L27 -> 0 | M28: =+M27 -> 0 | N28: FC_LC
A29: =+A28 -> 7 | B29: =+'libro compras'!$AB$1 -> 0131 | C29: =+C28 -> 103 | E29: =+E28 | G29: =-'libro compras'!I27 -> 0 | I29: 01 | J29: =+J28 | K29: =+K28 -> 0 | L29: =+L28 -> 0 | M29: =+M28 -> 0 | N29: FC_LC
A30: =1+A26 -> 8 | B30: =+'libro compras'!$AK$1 -> 281110 | C30: =+'libro compras'!Q31 -> 103 | E30: =+'libro compras'!S31 | G30: =+'libro compras'!AM31 -> 0 | I30: 00 | J30: =+CONCATENATE('libro compras'!C31," ",'libro compras'!D31) | K30: =+'libro compras'!F31 -> 0 | L30: =+'libro compras'!C31 -> 0 | M30: =+'libro compras'!D31 -> 0 | N30: FC_LC
A31: =+A30 -> 8 | B31: =+'libro compras'!$AL$1 -> 401110 | C31: =+C30 -> 103 | E31: =+E30 | G31: =+'libro compras'!L31 -> 0 | I31: 00 | J31: =+J30 | K31: =+K30 -> 0 | L31: =+L30 -> 0 | M31: =+M30 -> 0 | N31: FC_LC
A32: =+A31 -> 8 | B32: =+'libro compras'!$AN$1 -> 421202 | C32: =+C31 -> 103 | E32: =+E31 | G32: =-'libro compras'!H31 -> 0 | I32: 01 | J32: =+J31 | K32: =+K31 -> 0 | L32: =+L31 -> 0 | M32: =+M31 -> 0 | N32: FC_LC
A33: =+A32 -> 8 | B33: =+'libro compras'!$AB$1 -> 0131 | C33: =+C32 -> 103 | E33: =+E32 | G33: =-'libro compras'!I31 -> 0 | I33: 01 | J33: =+J32 | K33: =+K32 -> 0 | L33: =+L32 -> 0 | M33: =+M32 -> 0 | N33: FC_LC
A34: =1+A30 -> 9 | B34: =+'libro compras'!$AK$1 -> 281110 | C34: =+'libro compras'!Q35 -> 103 | E34: =+'libro compras'!S35 | G34: =+'libro compras'!AM35 -> 0 | I34: 00 | J34: =+CONCATENATE('libro compras'!C35," ",'libro compras'!D35) | K34: =+'libro compras'!F35 -> 0 | L34: =+'libro compras'!C35 -> 0 | M34: =+'libro compras'!D35 -> 0 | N34: FC_LC
A35: =+A34 -> 9 | B35: =+'libro compras'!$AL$1 -> 401110 | C35: =+C34 -> 103 | E35: =+E34 | G35: =+'libro compras'!L35 -> 0 | I35: 00 | J35: =+J34 | K35: =+K34 -> 0 | L35: =+L34 -> 0 | M35: =+M34 -> 0 | N35: FC_LC
A36: =+A35 -> 9 | B36: =+'libro compras'!$AN$1 -> 421202 | C36: =+C35 -> 103 | E36: =+E35 | G36: =-'libro compras'!H35 -> 0 | I36: 01 | J36: =+J35 | K36: =+K35 -> 0 | L36: =+L35 -> 0 | M36: =+M35 -> 0 | N36: FC_LC
A37: =+A36 -> 9 | B37: =+'libro compras'!$AB$1 -> 0131 | C37: =+C36 -> 103 | E37: =+E36 | G37: =-'libro compras'!I35 -> 0 | I37: 01 | J37: =+J36 | K37: =+K36 -> 0 | L37: =+L36 -> 0 | M37: =+M36 -> 0 | N37: FC_LC
A38: =1+A34 -> 10 | B38: =+'libro compras'!$AK$1 -> 281110 | C38: =+'libro compras'!Q39 -> 103 | E38: =+'libro compras'!S39 | G38: =+'libro compras'!AM39 -> 0 | I38: 00 | J38: =+CONCATENATE('libro compras'!C39," ",'libro compras'!D39) | K38: =+'libro compras'!F39 -> 0 | L38: =+'libro compras'!C39 -> 0 | M38: =+'libro compras'!D39 -> 0 | N38: FC_LC
A39: =+A38 -> 10 | B39: =+'libro compras'!$AL$1 -> 401110 | C39: =+C38 -> 103 | E39: =+E38 | G39: =+'libro compras'!L39 -> 0 | I39: 00 | J39: =+J38 | K39: =+K38 -> 0 | L39: =+L38 -> 0 | M39: =+M38 -> 0 | N39: FC_LC
A40: =+A39 -> 10 | B40: =+'libro compras'!$AN$1 -> 421202 | C40: =+C39 -> 103 | E40: =+E39 | G40: =-'libro compras'!H39 -> 0 | I40: 01 | J40: =+J39 | K40: =+K39 -> 0 | L40: =+L39 -> 0 | M40: =+M39 -> 0 | N40: FC_LC
...
